Workbook
Name _Hlk483005579: 'Cuadro 11'!#REF!
Name _Hlk483005579: 'Cuadro 12'!#REF!
Name _Hlk483005579: 'Cuadro 13'!#REF!
Name _Hlk483005846: 'Cuadro 11'!#REF!
Name _Hlk483005846: 'Cuadro 12'!#REF!
Name _Hlk483005846: 'Cuadro 13'!#REF!
Name _Hlk483070127: 'Cuadro 8'!#REF!
Name _Hlk483070810: 'Cuadro 20'!#REF!
Name _Hlk483070810: 'Cuadro 21'!#REF!
Name _Hlk483070810: 'Cuadro 22'!#REF!
Name OLE_LINK24: 'Cuadro 9'!#REF!
Name OLE_LINK25: 'Cuadro 20'!#REF!
Name OLE_LINK25: 'Cuadro 21'!#REF!
Name OLE_LINK25: 'Cuadro 22'!#REF!
Name OLE_LINK27: 'Cuadro 20'!#REF!
Name OLE_LINK27: 'Cuadro 21'!#REF!
Name OLE_LINK27: 'Cuadro 22'!#REF!
Name OLE_LINK28: 'Cuadro 20'!#REF!
Name OLE_LINK28: 'Cuadro 21'!#REF!
Name OLE_LINK28: 'Cuadro 22'!#REF!
Name OLE_LINK35: 'Cuadro 20'!$A$2
Name OLE_LINK35: 'Cuadro 21'!$A$2
Name OLE_LINK35: 'Cuadro 22'!$A$2
Name OLE_LINK35: #REF!

Sheet INDICE
A1: AUTOMOTORES - Coberturas de Casco | B1: ANEXO II
A3: Siniestros de Casco del Ramo Automotores - año 2024
A4: Información contenida | B4: Cuadro
A5: =+'Cuadro 1'!A2:O2 -> Cuadro 1: Vehículos Expuestos a Riesgo. Por Categoría de Cobertura. Por año. | B5: Cuadro 1
A6: =+'Cuadro 2'!A2:N2 -> Cuadro 2: Siniestros por Hecho Generador. Total por año | B6: Cuadro 2
A7: =+'Cuadro 3'!A2:M2 -> Cuadro 3: Vehículos Expuestos a Riesgo. Participación porcentual por Categoría de Cobertura. Por año | B7: Cuadro 3
A8: =+'Cuadro 4'!A2:L2 -> Cuadro 4: Frecuencia Siniestral por Hecho Generador. Por año | B8: Cuadro 4
A9: =+'Cuadro 5'!A2:L2 -> Cuadro 5: Siniestros por Tipo de Vehículo. Todos los Hechos Generadores de Casco. Por año | B9: Cuadro 5
A10: =+'Cuadro 6'!A2:L2 -> Cuadro 6: Vehículos Expuestos a Riesgo por Tipo de Vehículo. Participación por Tipo de Cobertura. Por año | B10: Cuadro 6
A11: =+'Cuadro 7'!A2:L2 -> Cuadro 7: Frecuencia Siniestral de Casco por Tipo de Vehículo. Todos los Hechos Generadores de Casco. Por año | B11: Cuadro 7
A12: =+'Cuadro 8'!A2:G2 -> Cuadro 8: Siniestros de Casco por Jurisdicción. Año 2024. Comparación con año 2023 | B12: Cuadro 8
A13: =+'Cuadro 9'!A2:P2 -> Cuadro 9: Siniestros de Casco por Jurisdicción, Zona y Hecho Generador. Año 2024 | B13: Cuadro 9
A14: =+'Cuadro 10'!A2:P2 -> Cuadro 10: Frecuencia Siniestral de Casco por Hecho Generador. Principales Zonas. Año 2024. Comparación con año 2023 | B14: Cuadro 10
A15: =+'Cuadro 11'!A2:L2 -> Cuadro 11: Siniestros de Robo Total por Tipo de Vehículo. Por año | B15: Cuadro 11
A16: =+'Cuadro 12'!A2:N2 -> Cuadro 12: Vehículos Expuestos a Riesgo con cobertura de Robo Total por Tipo de Vehículo. Por año | B16: Cuadro 12
A17: =+'Cuadro 13'!A2:L2 -> Cuadro 13: Frecuencia Siniestral de Robo Total por Tipo de Vehículo. Por año | B17: Cuadro 13
A18: =+'Cuadro 14'!A2:G2 -> Cuadro 14: Siniestros de Robo Total por Mes de ocurrencia | B18: Cuadro 14
A19: =+'Cuadro 15'!A2:J2 -> Cuadro 15: Siniestros de Robo Total por Tipo de Vehículo y Mes de ocurrencia. Año 2024 | B19: Cuadro 15
A20: =+'Cuadro 16'!A2:E2 -> Cuadro 16: Siniestros de Robo Total por Jurisdicción. Año 2024 | B20: Cuadro 16
A21: =+'Cuadro 17'!A2:M2 -> Cuadro 17: Siniestros de Robo Total por Jurisdicción. Por año | B21: Cuadro 17
A22: =+'Cuadro 18'!A2:M2 -> Cuadro 18: Vehículos Expuestos a Riesgo con cobertura de Robo Total por Jurisdicción. Por año | B22: Cuadro 18
A23: =+'Cuadro 19'!$A$2:$M$2 -> Cuadro 19: Frecuencia Siniestral de Robo Total por Jurisdicción. Por año | B23: Cuadro 19
A24: =+'Cuadro 20'!$A$2:$M$2 -> Cuadro 20: Siniestros de Robo Total por Tipo de Vehículo y Jurisdicción. Año 2024 | B24: Cuadro 20
A25: =+'Cuadro 21'!$A$2:$M$2 -> Cuadro 21: Vehículos Expuestos a Riesgo por Tipo de Vehículo y Jurisdicción. Cobertura de Robo Total. Año 2024 | B25: Cuadro 21
A26: =+'Cuadro 22'!$A$2:$M$2 -> Cuadro 22: Frecuencia Siniestral de Robo Total por Tipo de Vehículo y Jurisdicción. Año 2024 | B26: Cuadro 22
A27: =+'Cuadro 23'!$A$2:$M$2 -> Cuadro 23: Siniestros de Robo Total. Frecuencia Siniestral. Principales Tipos de Vehículo, Jurisdicciones y Zonas. | B27: Cuadro 23
A28: =+'Cuadro 24'!$A$2:$M$2 -> Cuadro 24: Siniestros de Robo Total. Partidos del Área Metropolitana. Año 2024 | B28: Cuadro 24
A29: =+'Cuadro 25'!$A$2:$M$2 -> Cuadro 25: Siniestros de Robo Total. Partidos del Área Metropolitana. Por año | B29: Cuadro 25
A30: =+'Cuadro 26'!$A$2:$M$2 -> Cuadro 26: Vehículos Expuestos a Riesgo con cobertura de Robo Total. Partidos del Área Metropolitana. Por año | B30: Cuadro 26
A31: =+'Cuadro 27'!$A$2:$M$2 -> Cuadro 27: Frecuencia Siniestral de Robo Total. Partidos del Área Metropolitana. Por año | B31: Cuadro 27
A32: =+'Cuadro 28'!$A$2:$M$2 -> Cuadro 28: Siniestros de Robo Total. Partidos del Área Metropolitana. Principales Tipos de Vehículo. Año 2024 | B32: Cuadro 28
A33: =+'Cuadro 29'!$A$2:$M$2 -> Cuadro 29: Vehículos Expuestos a Riesgo con cobertura de Robo Total. Partidos del Área Metropolitana. Principales Tipos de Vehículo. Año 2024 | B33: Cuadro 29
A34: =+'Cuadro 30'!$A$2:$M$2 -> Cuadro 30: Frecuencia Siniestral de Robo Total. Partidos del Área Metropolitana. Principales Tipos de Vehículo. Año 2024 | B34: Cuadro 30
A35: =+'Cuadro 31'!$A$2:$N$2 -> Cuadro 31: Siniestros de Robo Total por Año de Fabricación y Tipo de Vehículo. Año 2024 | B35: Cuadro 31
A36: =+'Cuadro 32'!$A$2:$M$2 -> Cuadro 32: Automóviles. Siniestros de Robo Total. Ranking por Marca y Modelo. Año 2024 | B36: Cuadro 32
A37: =+'Cuadro 33'!$A$2:$M$2 -> Cuadro 33: Motos. Siniestros de Robo Total. Ranking por Marca y Modelo. Año 2024 | B37: Cuadro 33

Sheet Cuadro 1
A1: AUTOMOTORES - Coberturas de Casco | Q1: INDICE
A2: Cuadro 1: Vehículos Expuestos a Riesgo. Por Categoría de Cobertura. Por año. | N2: Var. | O2: Var.
A4: Categoría de Cobertura | C4: Año | M4: Part. 2024 | N4: Var. | O4: Var.
N5: (24 / 23) | O5: (24 / 15)
C6: 2015 | D6: 2016 | E6: 2017 | F6: 2018 | G6: 2019 | H6: 2020 | I6: 2021 | J6: 2022 | K6: 2023 | L6: 2024 | M6: % | N6: % | O6: %
B7: TOTAL | C7: 11055593 | D7: 11382312 | E7: 12079792 | F7: 13062191 | G7: 13233632 | H7: 13205558 | I7: 13897229 | J7: 14526548 | K7: 15014323 | L7: 14889353 | M7: 1 | N7: =+L7/K7-1 -> -0.0083233856 | O7: =+L7/C7-1 -> 0.34677109
A8: A | B8: Responsabilidad Civil (RC) | C8: 3475173.3 | D8: 3531115.5 | E8: 3744199.6 | F8: 3985237.2 | G8: 3950556.3 | H8: 4000761.9 | I8: 4313924.5 | J8: 4787730.8 | K8: 4969477.2 | L8: 5252846.7 | M8: 0.35279214 | N8: 0.057021984 | O8: 0.51153518
A9: B | B9: RC, Robo Total, Incendio Total, Daño Total | C9: 457961.5 | D9: 484896.54 | E9: 446230.34 | F9: 464034.57 | G9: 460686.51 | H9: 470932.14 | I9: 504823.36 | J9: 488065.07 | K9: 552918.91 | L9: 554460.33 | M9: 0.037238712 | N9: 0.0027877774 | O9: 0.21071385
A10: B1 | B10: RC, Robo Total, Incendio Total | C10: 612568.33 | D10: 636940.23 | E10: 735926.92 | F10: 813207.63 | G10: 770522.65 | H10: 771836.18 | I10: 855109.09 | J10: 910891.45 | K10: 986237.62 | L10: 952194.42 | M10: 0.063951363 | N10: -0.034518248 | O10: 0.55442973
A11: C | B11: RC, Robo Total y Parcial, Incendio Total y Parcial, Daño Total | C11: 3481333.8 | D11: 3601590.7 | E11: 3727360.9 | F11: 3971449.3 | G11: 4007146.3 | H11: 3883992.3 | I11: 4023658.1 | J11: 3942260.2 | K11: 3936149.8 | L11: 3945932 | M11: 0.26501702 | N11: 0.0024852214 | O11: 0.13345407
A12: C1 | B12: RC, Robo Total y Parcial, Incendio Total y Parcial | C12: 536902.15 | D12: 531703.73 | E12: 479992.56 | F12: 483462.27 | G12: 491313.71 | H12: 452470.2 | I12: 481284.44 | J12: 451142.85 | K12: 416839.66 | L12: 329998.64 | M12: 0.022163397 | N12: -0.20833195 | O12: -0.38536541
A13: D | B13: RC, Robo Total y Parcial, Incendio Total y Parcial, Daño Total y Parcial | C13: 1995629 | D13: 2109697.9 | E13: 2364547.7 | F13: 2658044.3 | G13: 2893325.7 | H13: 2897452.1 | I13: 2822672.3 | J13: 2793164.2 | K13: 2874384.6 | L13: 2788362.3 | M13: 0.18727223 | N13: -0.029927188 | O13: 0.3972348
A14: OTRAS | B14: RC y coberturas de casco varias | C14: 496024.86 | D14: 486367.44 | E14: 581534.01 | F14: 686755.81 | G14: 659483.4 | H14: 726624.53 | I14: 895591.71 | J14: 1153293.4 | K14: 1278315.2 | L14: 1065558.6 | M14: 0.071565138 | N14: -0.16643517 | O14: 1.148196

Sheet Cuadro 2
A1: AUTOMOTORES - Coberturas de Casco | P1: INDICE
A2: Cuadro 2: Siniestros por Hecho Generador. Total por año
A4: Hecho Generador | B4: Año | L4: Part. 2024 | M4: Var. | N4: Var.
M5: (24 / 23) | N5: (24 / 15)
B6: 2015 | C6: 2016 | D6: 2017 | E6: 2018 | F6: 2019 | G6: 2020 | H6: 2021 | I6: 2022 | J6: 2023 | K6: 2024 | L6: % | M6: % | N6: %
A7: Total | B7: 1516301 | C7: 1607783 | D7: 1767030 | E7: 1972543 | F7: 2001151 | G7: 1359599 | H7: 1847608 | I7: 2142876 | J7: 2218125 | K7: 2077069 | L7: 1 | M7: -0.063592449 | N7: 0.36982631
A8: Robo Total | B8: 66872 | C8: 69988 | D8: 68320 | E8: 68736 | F8: 74237 | G8: 54257 | H8: 65867 | I8: 83572 | J8: 104051 | K8: 108775 | L8: 0.052369469 | M8: 0.045400813 | N8: 0.62661503
A9: Robo Parcial | B9: 233026 | C9: 236545 | D9: 215676 | E9: 215528 | F9: 260296 | G9: 215426 | H9: 314436 | I9: 382960 | J9: 407031 | K9: 367675 | L9: 0.17701627 | M9: -0.096690424 | N9: 0.57782823
A10: Incendio Total | B10: 3008 | C10: 3429 | D10: 3752 | E10: 3861 | F10: 4262 | G10: 3440 | H10: 4365 | I10: 5048 | J10: 6048 | K10: 7663 | L10: 0.0036893334 | M10: 0.26703042 | N10: 1.5475399
A11: Incendio Parcial | B11: 6505 | C11: 6361 | D11: 5832 | E11: 8980 | F11: 5227 | G11: 3900 | H11: 4578 | I11: 4896 | J11: 4931 | K11: 4576 | L11: 0.0022031045 | M11: -0.07199351 | N11: -0.29654112
A12: Daño Total | B12: 32545 | C12: 35024 | D12: 42894 | E12: 50161 | F12: 52796 | G12: 31771 | H12: 38638 | I12: 39849 | J12: 45362 | K12: 44923 | L12: 0.021628073 | M12: -0.0096777038 | N12: 0.38033492
A13: Daño Parcial | B13: 1174345 | C13: 1256436 | D13: 1430556 | E13: 1625277 | F13: 1604333 | G13: 1050805 | H13: 1419724 | I13: 1626551 | J13: 1650702 | K13: 1543457 | L13: 0.74309375 | M13: -0.064969328 | N13: 0.31431309

Sheet Cuadro 3
A1: AUTOMOTORES - Coberturas de Casco | O1: INDICE
A2: Cuadro 3: Vehículos Expuestos a Riesgo. Participación porcentual por Categoría de Cobertura. Por año
A4: Categoría de Cobertura | C4: Año | M4: Var. (en p.p.)*
C5: 2015 | D5: 2016 | E5: 2017 | F5: 2018 | G5: 2019 | H5: 2020 | I5: 2021 | J5: 2022 | K5: 2023 | L5: 2024
B6: TOTAL | C6: 1 | D6: 1 | E6: 1 | F6: 1 | G6: 1 | H6: 1 | I6: 1 | J6: 1 | K6: 1 | L6: 1
A7: A | B7: Responsabilidad Civil (RC) | C7: 0.31433622 | D7: 0.31022832 | E7: 0.30995563 | F7: 0.30509715 | G7: 0.29853744 | H7: 0.30299461 | I7: 0.31041986 | J7: 0.3295849 | K7: 0.33098244 | L7: 0.35279214 | M7: 2.18
A8: B | B8: RC, Robo Total, Incendio Total, Daño Total | C8: 0.041423513 | D8: 0.042600883 | E8: 0.036940233 | F8: 0.035525018 | G8: 0.034813369 | H8: 0.035665683 | I8: 0.036325902 | J8: 0.033598146 | K8: 0.036826097 | L8: 0.037238712 | M8: 0.04
A9: B1 | B9: RC, Robo Total, Incendio Total | C9: 0.055408003 | D9: 0.055958775 | E9: 0.060922152 | F9: 0.062256603 | G9: 0.058227207 | H9: 0.058454418 | I9: 0.061531638 | J9: 0.062705293 | K9: 0.065686453 | L9: 0.063951363 | M9: -0.17
A10: C | B10: RC, Robo Total y Parcial, Incendio Total y Parcial, Daño Total | C10: 0.31489345 | D10: 0.31641996 | E10: 0.30856168 | F10: 0.30404159 | G10: 0.30281386 | H10: 0.29415116 | I10: 0.28953297 | J10: 0.27138314 | K10: 0.26215966 | L10: 0.26501702 | M10: 0.28
A11: C1 | B11: RC, Robo Total y Parcial, Incendio Total y Parcial | C11: 0.048563849 | D11: 0.046713157 | E11: 0.039735167 | F11: 0.037012341 | G11: 0.037127819 | H11: 0.034267481 | I11: 0.034632096 | J11: 0.031056439 | K11: 0.027762801 | L11: 0.022163397 | M11: -0.56
A12: D | B12: RC, Robo Total y Parcial, Incendio Total y Parcial, Daño Total y Parcial | C12: 0.18050855 | D12: 0.1853488 | E12: 0.19574407 | F12: 0.20349146 | G12: 0.21864415 | H12: 0.2194363 | I12: 0.20311286 | J12: 0.19227997 | K12: 0.19144284 | L12: 0.18727223 | M12: -0.41
A13: OTRAS | B13: RC y coberturas de casco varias | C13: 0.044866419 | D13: 0.04273011 | E13: 0.048141061 | F13: 0.052575851 | G13: 0.049836143 | H13: 0.055030348 | I13: 0.064444673 | J13: 0.079392118 | K13: 0.085139717 | L13: 0.071565138 | M13: -1.35
A15: * puntos porcentuales

Sheet Cuadro 4
A1: AUTOMOTORES - Coberturas de Casco | N1: INDICE
A2: Cuadro 4: Frecuencia Siniestral por Hecho Generador. Por año
A4: Hecho Generador | B4: Año | L4: Var. (en p.p.)*
B5: 2015 | C5: 2016 | D5: 2017 | E5: 2018 | F5: 2019 | G5: 2020 | H5: 2021 | I5: 2022 | J5: 2023 | K5: 2024
A6: Total | B6: 0.20002863 | C6: 0.20478191 | D6: 0.21198613 | E6: 0.21731332 | F6: 0.2155837 | G6: 0.14772939 | H6: 0.19279779 | I6: 0.22003452 | J6: 0.22082221 | K6: 0.2155417 | L6: -0.53
A7: Robo Total | B7: 0.0088216751 | C7: 0.0089143101 | D7: 0.0081961781 | E7: 0.0075725845 | F7: 0.0079975409 | G7: 0.0058953806 | H7: 0.0068732176 | I7: 0.0085813296 | J7: 0.010358646 | K7: 0.011287805 | L7: 0.09
A8: Robo Parcial | B8: 0.038748126 | C8: 0.037889683 | D8: 0.032817901 | E8: 0.030300765 | F8: 0.035214224 | G8: 0.029780003 | H8: 0.042911098 | I8: 0.053288307 | J8: 0.056317965 | K8: 0.052046964 | L8: -0.43
A9: Incendio Total | B9: 0.0003968118 | C9: 0.00043674872 | D9: 0.00045011798 | E9: 0.00042536297 | F9: 0.00045914462 | G9: 0.00037377867 | H9: 0.0004554875 | I9: 0.0005183381 | J9: 0.00060209984 | K9: 0.00079520521 | L9: 0.02
A10: Incendio Parcial | B10: 0.0008581319 | C10: 0.00081019498 | D10: 0.00069965033 | E10: 0.00098931869 | F10: 0.00056310393 | G10: 0.0004237607 | H10: 0.00047771403 | I10: 0.00050273046 | J10: 0.00049089853 | K10: 0.00047486089 | L10: 0
A11: Daño Total | B11: 0.0042932979 | C11: 0.0044609761 | D11: 0.005145885 | E11: 0.0055261932 | F11: 0.0056877052 | G11: 0.0034521285 | H11: 0.004031873 | I11: 0.00409177 | J11: 0.0045159479 | K11: 0.0046617517 | L11: 0.02
A12: Daño Parcial | B12: 0.58845856 | C12: 0.59555258 | D12: 0.60500197 | E12: 0.61145596 | F12: 0.55449444 | G12: 0.36266518 | H12: 0.5029716 | I12: 0.58233275 | J12: 0.57428014 | K12: 0.5535353 | L12: -2.08
A14: * puntos porcentuales

Sheet Cuadro 5
A1: AUTOMOTORES - Coberturas de Casco | P1: INDICE
A2: Cuadro 5: Siniestros por Tipo de Vehículo. Todos los Hechos Generadores de Casco. Por año
A4: Tipo de Vehículo | B4: Año | L4: Part. 2024 | M4: Var. | N4: Var.
M5: (24 / 23) | N5: (24 / 15)
B6: 2015 | C6: 2016 | D6: 2017 | E6: 2018 | F6: 2019 | G6: 2020 | H6: 2021 | I6: 2022 | J6: 2023 | K6: 2024 | L6: % | M6: % | N6: %
A7: Total | B7: 1516301 | C7: 1607783 | D7: 1767030 | E7: 1972543 | F7: 2001151 | G7: 1359599 | H7: 1847608 | I7: 2142876 | J7: 2218125 | K7: 2077069 | L7: 1 | M7: -0.063592449 | N7: 0.36982631
A8: Autos | B8: 1384432 | C8: 1456752 | D8: 1603373 | E8: 1783395 | F8: 1802549 | G8: 1205118 | H8: 1644322 | I8: 1888557 | J8: 1937103 | K8: 1795508 | L8: 0.86444312 | M8: -0.073096268 | N8: 0.29692755
A9: Camionetas | B9: 82278 | C9: 95842 | D9: 109851 | E9: 125516 | F9: 131767 | G9: 100979 | H9: 142265 | I9: 173108 | J9: 183691 | K9: 188425 | L9: 0.090716774 | M9: 0.02577154 | N9: 1.2901018
A10: Camiones | B10: 10294 | C10: 10750 | D10: 10379 | E10: 12130 | F10: 13076 | G10: 12738 | H10: 17141 | I10: 20436 | J10: 21047 | K10: 18831 | L10: 0.0090661408 | M10: -0.10528816 | N10: 0.82931805
A11: Taxis | B11: 3734 | C11: 4141 | D11: 4630 | E11: 6807 | F11: 4632 | G11: 2758 | H11: 2816 | I11: 2927 | J11: 2906 | K11: 2436 | L11: 0.0011728065 | M11: -0.16173434 | N11: -0.3476165
A12: Remises | B12: 3613 | C12: 3715 | D12: 4220 | E12: 4519 | F12: 4105 | G12: 2423 | H12: 2799 | I12: 2687 | J12: 2372 | K12: 2135 | L12: 0.0010278907 | M12: -0.099915683 | N12: -0.40907833
A13: Motos | B13: 28397 | C13: 32750 | D13: 30807 | E13: 36216 | F13: 40603 | G13: 32015 | H13: 33415 | I13: 49094 | J13: 64288 | K13: 63365 | L13: 0.030506931 | M13: -0.014357267 | N13: 1.2313977
A14: Máquinas Rurales | B14: 2127 | C14: 2233 | D14: 2047 | E14: 2274 | F14: 2315 | G14: 2260 | H14: 2841 | I14: 3157 | J14: 3039 | K14: 2513 | L14: 0.001209878 | M14: -0.17308325 | N14: 0.18147626
A15: M1+M2+M3 | B15: 1426 | C15: 1600 | D15: 1723 | E15: 1686 | F15: 2104 | G15: 1308 | H15: 2009 | I15: 2910 | J15: 3679 | K15: 3856 | L15: 0.0018564622 | M15: 0.0481109 | N15: 1.7040673
A17: Autos | B17: Autómoviles, camionetas rurales, breaks, jeeps hasta 4 cilindros, pick up A.
A18: Camionetas | B18: Jeeps más de 4 cilindros, pick up B, casas rodantes con propulsión propia.
A19: Camiones | B19: Camiones, semitracción.
A20: Máquinas Rurales | B20: Tractores, máquinas rurales, acoplados para trabajos rurales, acoplados, furgones, semirremolques, casas rodantes sin propulsión propia, trailer, bantam.
A21: M1+M2+M3 | B21: M1: vehículo para transporte de pasajeros, que no contenga más de 8 asientos además del asiento del conductor y que cargado no exceda de un peso máximo de 3500 Kg.
B22: M2: vehículo para transporte de pasajeros con más de 8 asientos excluyendo el asiento del conductor, y que no exceda el peso máximo de 5000 Kg.
B23: M3: vehículo para transporte de pasajeros con más de 8 asientos excluyendo el asiento del conductor, y que tenga un peso mayor a los 5000 Kg.

Sheet Cuadro 6
A1: AUTOMOTORES - Coberturas de Casco | N1: INDICE
A2: Cuadro 6: Vehículos Expuestos a Riesgo por Tipo de Vehículo. Participación por Tipo de Cobertura. Por año
A4: Tipo de Vehículo | B4: Año | L4: Var.
B5: 2015 | C5: 2016 | D5: 2017 | E5: 2018 | F5: 2019 | G5: 2020 | H5: 2021 | I5: 2022 | J5: 2023 | K5: 2024
A6: Total | B6: 11055593 | C6: 11382312 | D6: 12079792 | E6: 13062191 | F6: 13233632 | G6: 13205558 | H6: 13897229 | I6: 14526548 | J6: 15014323 | K6: 14889353 | L6: =+K6/J6-1 -> -0.0083233856
A7: Autos | B7: 7688976 | C7: 7830700 | D7: 8217233 | E7: 8848575 | F7: 8950333.5 | G7: 8881410.8 | H7: 9210164.6 | I7: 9545672 | J7: 9790984 | K7: 9652932 | L7: -0.014099911
A8: RC + Casco | B8: 0.82116871 | C8: 0.82531936 | D8: 0.82882325 | E8: 0.83067749 | F8: 0.83929243 | G8: 0.83516121 | H8: 0.82948761 | I8: 0.79822238 | J8: 0.79361859 | K8: 0.76639145
A9: RC | B9: 0.17883129 | C9: 0.17468064 | D9: 0.17117675 | E9: 0.16932251 | F9: 0.16070757 | G9: 0.16483879 | H9: 0.17051239 | I9: 0.20177762 | J9: 0.20638141 | K9: 0.23360855
A10: Camionetas | B10: 850913 | C10: 890324 | D10: 931253 | E10: 1008835 | F10: 1040350.6 | G10: 1043042.7 | H10: 1106938.9 | I10: 1182329 | J10: 1220647 | K10: 1272836 | L10: 0.042755195
A11: RC + Casco | B11: 0.60998059 | C11: 0.62476078 | D11: 0.64459662 | E11: 0.66528185 | F11: 0.67746718 | G11: 0.66521725 | H11: 0.66657538 | I11: 0.64836502 | J11: 0.64196229 | K11: 0.62822167
A12: RC | B12: 0.39001941 | C12: 0.37523922 | D12: 0.35540338 | E12: 0.33471815 | F12: 0.32253282 | G12: 0.33478275 | H12: 0.33342462 | I12: 0.35163498 | J12: 0.35803771 | K12: 0.37177833
A13: Camiones | B13: 399865 | C13: 398536 | D13: 421200 | E13: 436540 | F13: 438300.36 | G13: 433566.6 | H13: 436955.65 | I13: 469864 | J13: 489679 | K13: 496490 | L13: 0.013909112
A14: RC + Casco | B14: 0.47031654 | C14: 0.47263616 | D14: 0.47027382 | E14: 0.46621676 | F14: 0.46581961 | G14: 0.45817793 | H14: 0.45247335 | I14: 0.43979392 | J14: 0.44555247 | K14: 0.42329883
A15: RC | B15: 0.52968346 | C15: 0.52736384 | D15: 0.52972618 | E15: 0.53378324 | F15: 0.53418039 | G15: 0.54182207 | H15: 0.54752665 | I15: 0.56020608 | J15: 0.55444753 | K15: 0.57670117
A16: Taxis | B16: 79310 | C16: 78793 | D16: 73842 | E16: 90859 | F16: 86940 | G16: 72001 | H16: 69165 | I16: 64061 | J16: 54114 | K16: 54308 | L16: 0.0035850242
A17: RC + Casco | B17: 0.66360803 | C17: 0.68204038 | D17: 0.70022926 | E17: 0.67132926 | F17: 0.67357521 | G17: 0.68409414 | H17: 0.62875701 | I17: 0.53681051 | J17: 0.47538772 | K17: 0.4329821
A18: RC | B18: 0.33639197 | C18: 0.31795962 | D18: 0.29977074 | E18: 0.32867074 | F18: 0.32642479 | G18: 0.31590586 | H18: 0.37124299 | I18: 0.46318949 | J18: 0.52461228 | K18: 0.5670179
A19: Remises | B19: 70905 | C19: 71785 | D19: 66064 | E19: 59311 | F19: 53069 | G19: 42850.328 | H19: 46492 | I19: 38860 | J19: 53306 | K19: 34860 | L19: -0.34603985
A20: RC + Casco | B20: 0.65663381 | C20: 0.6952004 | D20: 0.73102659 | E20: 0.72504814 | F20: 0.73658144 | G20: 0.79719852 | H20: 0.77430708 | I20: 0.64961462 | J20: 0.67373711 | K20: 0.50438051
A21: RC | B21: 0.34336619 | C21: 0.3047996 | D21: 0.26897341 | E21: 0.27495186 | F21: 0.26341856 | G21: 0.20280148 | H21: 0.22569292 | I21: 0.35038538 | J21: 0.32626289 | K21: 0.49561949
A22: Motos | B22: 1213251 | C22: 1349973 | D22: 1566332 | E22: 1788926 | F22: 1810058.3 | G22: 1895407.8 | H22: 2127071.1 | I22: 2291781 | J22: 2451291 | K22: 2414097 | L22: -0.015173229
A23: RC + Casco | B23: 0.2608079 | C23: 0.29544844 | D23: 0.30716434 | E23: 0.33618551 | F23: 0.34127141 | G23: 0.34819503 | H23: 0.36514179 | I23: 0.40403382 | J23: 0.41392964 | K23: 0.40848088
A24: RC | B24: 0.7391921 | C24: 0.70455156 | D24: 0.69283566 | E24: 0.66381449 | F24: 0.65872859 | G24: 0.65180497 | H24: 0.63485821 | I24: 0.59596618 | J24: 0.58607036 | K24: 0.59151912
A25: Maq rurales | B25: 662565 | C25: 672002 | D25: 713889 | E25: 738285 | F25: 762678.85 | G25: 752060.01 | H25: 815391.4 | I25: 844992 | J25: 860286 | K25: 864165 | L25: 0.0045089656
A26: RC + Casco | B26: 0.17170621 | C26: 0.1655706 | D26: 0.16172332 | E26: 0.15640056 | F26: 0.14983634 | G26: 0.15184699 | H26: 0.14893083 | I26: 0.15226455 | J26: 0.17502625 | K26: 0.17945769
A27: RC | B27: 0.82829379 | C27: 0.8344294 | D27: 0.83827668 | E27: 0.84359944 | F27: 0.85016366 | G27: 0.84815301 | H27: 0.85106917 | I27: 0.84773545 | J27: 0.82497375 | K27: 0.82054231
A28: M1+M2+M3 | B28: 89808 | C28: 90199 | D28: 89979 | E28: 90860 | F28: 91304 | G28: 83730 | H28: 84885 | I28: 88989 | J28: 94016 | K28: 99665 | L28: 0.060085517
A29: RC + Casco | B29: 0.33391601 | C29: 0.33270903 | D29: 0.3336572 | E29: 0.34207628 | F29: 0.34949616 | G29: 0.42770429 | H29: 0.35631939 | I29: 0.35703309 | J29: 0.48797951 | K29: 0.46660724
A30: RC | B30: 0.66608399 | C30: 0.66729097 | D30: 0.6663428 | E30: 0.65792372 | F30: 0.65050384 | G30: 0.57229571 | H30: 0.64368061 | I30: 0.64296691 | J30: 0.51202049 | K30: 0.53339276
A32: Autos | B32: Autómoviles, camionetas rurales, breaks, jeeps hasta 4 cilindros, pick up A.
A33: Camionetas | B33: Jeeps más de 4 cilindros, pick up B, casas rodantes con propulsión propia.
A34: Camiones | B34: Camiones, semitracción.
A35: Máquinas Rurales | B35: Tractores, máquinas rurales, acoplados para trabajos rurales, acoplados, furgones, semirremolques, casas rodantes sin propulsión propia, trailer, bantam.
A36: M1+M2+M3 | B36: M1: vehículo para transporte de pasajeros, que no contenga más de 8 asientos además del asiento del conductor y que cargado no exceda de un peso máximo de 3500 Kg.
B37: M2: vehículo para transporte de pasajeros con más de 8 asientos excluyendo el asiento del conductor, y que no exceda el peso máximo de 5000 Kg.
B38: M3: vehículo para transporte de pasajeros con más de 8 asientos excluyendo el asiento del conductor, y que tenga un peso mayor a los 5000 Kg.

Sheet Cuadro 7
A1: AUTOMOTORES - Coberturas de Casco | N1: INDICE
A2: Cuadro 7: Frecuencia Siniestral de Casco por Tipo de Vehículo. Todos los Hechos Generadores de Casco. Por año
A4: Hecho Generador | B4: Año | L4: Var. (en p.p.)*
B5: 2015 | C5: 2016 | D5: 2017 | E5: 2018 | F5: 2019 | G5: 2020 | H5: 2021 | I5: 2022 | J5: 2023 | K5: 2024
A6: Total | B6: 0.20002863 | C6: 0.20478191 | D6: 0.21198613 | E6: 0.21731332 | F6: 0.2155837 | G6: 0.14772939 | H6: 0.19279779 | I6: 0.22003452 | J6: 0.22082221 | K6: 0.2155417 | L6: -0.53
A7: Autos | B7: 0.21926572 | C7: 0.22540472 | D7: 0.235422 | E7: 0.24262847 | F7: 0.23995762 | G7: 0.16247154 | H7: 0.21523336 | I7: 0.24785614 | J7: 0.24929556 | K7: 0.24270429 | L7: -0.66
A8: Camionetas | B8: 0.15851945 | C8: 0.17230347 | D8: 0.18299883 | E8: 0.18701364 | F8: 0.18695569 | G8: 0.14553433 | H8: 0.19280805 | I8: 0.22581835 | J8: 0.23441655 | K8: 0.23564225 | L8: 0.12
A9: Camiones | B9: 0.054736941 | C9: 0.057070801 | D9: 0.052398197 | E9: 0.059600358 | F9: 0.064045012 | G9: 0.064122619 | H9: 0.086697343 | I9: 0.098895038 | J9: 0.096467244 | K9: 0.089601608 | L9: -0.69
A10: Taxis | B10: 0.070947114 | C10: 0.077056185 | D10: 0.089544164 | E10: 0.11159692 | F10: 0.079097511 | G10: 0.05599379 | H10: 0.064753527 | I10: 0.085115371 | J10: 0.11296347 | K10: 0.10359613 | L10: -0.94
A11: Remises | B11: 0.077601097 | C11: 0.074441497 | D11: 0.087380478 | E11: 0.10508488 | F11: 0.10501504 | G11: 0.070930461 | H11: 0.077751976 | I11: 0.10644103 | J11: 0.066046243 | K11: 0.12142614 | L11: 5.54
A12: Motos | B12: 0.089743099 | C12: 0.082111601 | D12: 0.064031665 | E12: 0.060218387 | F12: 0.065730307 | G12: 0.048509665 | H12: 0.043022725 | I12: 0.053019739 | J12: 0.06335903 | K12: 0.064257376 | L12: 0.09
A13: Máquinas Rurales | B13: 0.018696185 | C13: 0.020069426 | D13: 0.017730235 | E13: 0.019693736 | F13: 0.020257793 | G13: 0.01979018 | H13: 0.023394862 | I13: 0.024537097 | J13: 0.02018295 | K13: 0.016204429 | L13: -0.4
A14: M1+M2+M3 | B14: 0.047551833 | C14: 0.053315523 | D14: 0.057390976 | E14: 0.05424527 | F14: 0.065934622 | G14: 0.036524396 | H14: 0.06642163 | I14: 0.091590027 | J14: 0.080191148 | K14: 0.082916867 | L14: 0.27
A16: * puntos porcentuales
A18: Autos | B18: Autómoviles, camionetas rurales, breaks, jeeps hasta 4 cilindros, pick up A.
A19: Camionetas | B19: Jeeps más de 4 cilindros, pick up B, casas rodantes con propulsión propia.
A20: Camiones | B20: Camiones, semitracción.
A21: Máquinas Rurales | B21: Tractores, máquinas rurales, acoplados para trabajos rurales, acoplados, furgones, semirremolques, casas rodantes sin propulsión propia, trailer, bantam.
A22: M1+M2+M3 | B22: M1: vehículo para transporte de pasajeros, que no contenga más de 8 asientos además del asiento del conductor y que cargado no exceda de un peso máximo de 3500 Kg.
B23: M2: vehículo para transporte de pasajeros con más de 8 asientos excluyendo el asiento del conductor, y que no exceda el peso máximo de 5000 Kg.
B24: M3: vehículo para transporte de pasajeros con más de 8 asientos excluyendo el asiento del conductor, y que tenga un peso mayor a los 5000 Kg.

Sheet Cuadro 8
A1: AUTOMOTORES - Coberturas de Casco | I1: INDICE
A2: Cuadro 8: Siniestros de Casco por Jurisdicción. Año 2024. Comparación con año 2023
A4: Jurisdicción | C4: 2024 | D4: Part.% | E4: 2023 | F4: Part.% | G4: Var. %
A5: Total | C5: 2077069 | D5: 1 | E5: 2218125 | F5: 1 | G5: -0.063592449
A6: C.A.B.A. | C6: 257259 | D6: 0.12385674 | E6: 264380 | F6: 0.11919076 | G6: -0.026934715
A7: A.M.B.A. | C7: 914794 | D7: 0.44042543 | E7: 962008 | F7: 0.43370324 | G7: -0.049078594
A8: Buenos Aires | C8: 963034 | D8: 0.46365046 | E8: 1022102 | F8: 0.46079549 | G8: -0.05779071
B9: Gran La Plata | C9: 68406 | D9: 0.032933908 | E9: 74692 | F9: 0.033673485 | G9: -0.084158946
B10: Noreste | C10: 98702 | D10: 0.047519846 | E10: 104406 | F10: 0.047069484 | G10: -0.054632876
B11: Noroeste | C11: 67433 | D11: 0.03246546 | E11: 73284 | F11: 0.033038715 | G11: -0.079840074
B12: Norte Centro | C12: 85167 | D12: 0.041003452 | E12: 90399 | F12: 0.040754691 | G12: -0.057876746
B13: Oeste | C13: 47248 | D13: 0.022747439 | E13: 49783 | F13: 0.022443731 | G13: -0.050920997
B14: Sur | C14: 34741 | D14: 0.016725973 | E14: 34664 | F14: 0.015627613 | G14: 0.0022213247
B15: Sureste | C15: 117348 | D15: 0.056496919 | E15: 123520 | F15: 0.055686672 | G15: -0.049967617
B16: Suroeste | C16: 138506 | D16: 0.066683389 | E16: 146884 | F16: 0.066219893 | G16: -0.057038207
B17: Bahía Blanca | C17: 21141 | D17: 0.010178285 | E17: 24013 | F17: 0.01082581 | G17: -0.11960188
B18: Gral Pueyrredón | C18: 68512 | D18: 0.032984942 | E18: 71137 | F18: 0.032070781 | G18: -0.036900628
B19: Resto Bs As | C19: 215830 | D19: 0.10391085 | E19: 229319 | F19: 0.10338416 | G19: -0.05882199
A20: Catamarca | C20: 4210 | D20: 0.0020268946 | E20: 4597 | F20: 0.0020724711 | G20: -0.084185338
A21: Chaco | C21: 17261 | D21: 0.008310268 | E21: 18462 | F21: 0.008323246 | G21: -0.06505254
A22: Chubut | C22: 40685 | D22: 0.019587698 | E22: 46276 | F22: 0.020862666 | G22: -0.12081857
A23: Córdoba | C23: 185149 | D23: 0.089139552 | E23: 211597 | F23: 0.095394534 | G23: -0.12499232
B24: Córdoba capital | C24: 93030 | D24: 0.044789075 | E24: 108847 | F24: 0.049071626 | G24: -0.14531406
A25: Corrientes | C25: 14894 | D25: 0.0071706814 | E25: 16632 | F25: 0.0074982249 | G25: -0.10449735
A26: Entre Ríos | C26: 45917 | D26: 0.022106632 | E26: 49299 | F26: 0.022225528 | G26: -0.068601797
A27: Formosa | C27: 4210 | D27: 0.0020268946 | E27: 5528 | F27: 0.002492195 | G27: -0.23842258
A28: Jujuy | C28: 7061 | D28: 0.0033995019 | E28: 7749 | F28: 0.0034934911 | G28: -0.08878565
A29: La Pampa | C29: 18811 | D29: 0.0090565118 | E29: 19257 | F29: 0.0086816568 | G29: -0.023160409
A30: La Rioja | C30: 2378 | D30: 0.0011448825 | E30: 2659 | F30: 0.0011987602 | G30: -0.10567883
A31: Mendoza | C31: 91633 | D31: 0.044116493 | E31: 87148 | F31: 0.039289039 | G31: 0.051464176
B32: Gran Mendoza | C32: 56643 | D32: 0.02727064 | E32: 54582 | F32: 0.02460727 | G32: 0.037759701
A33: Misiones | C33: 13281 | D33: 0.0063941063 | E33: 22512 | F33: 0.010149112 | G33: -0.41004797
A34: Neuquén | C34: 69713 | D34: 0.03356316 | E34: 72077 | F34: 0.032494562 | G34: -0.032798257
A35: Río Negro | C35: 29189 | D35: 0.014052976 | E35: 31552 | F35: 0.014224627 | G35: -0.074892241
A36: Salta | C36: 6131 | D36: 0.0029517556 | E36: 6314 | F36: 0.0028465483 | G36: -0.028983212
A37: San Juan | C37: 14647 | D37: 0.0070517638 | E37: 10826 | F37: 0.0048806988 | G37: 0.35294661
A38: San Luis | C38: 13354 | D38: 0.006429252 | E38: 15877 | F38: 0.0071578473 | G38: -0.15890911
A39: Santa Cruz | C39: 12309 | D39: 0.0059261392 | E39: 13341 | F39: 0.0060145393 | G39: -0.077355521
A40: Santa Fe | C40: 203082 | D40: 0.097773353 | E40: 217246 | F40: 0.097941279 | G40: -0.065197978
B41: Rosario | C41: 82704 | D41: 0.039817647 | E41: 86033 | F41: 0.038786362 | G41: -0.038694454
...

Sheet Cuadro 9
A1: AUTOMOTORES - Coberturas de Casco | R1: INDICE
A2: Cuadro 9: Siniestros de Casco por Jurisdicción, Zona y Hecho Generador. Año 2024
A4: Jurisdicción | C4: Total | E4: Robo Total | G4: Robo Parcial | I4: Incendio Total | K4: Incendio Parcial | M4: Daño Total | O4: Daño Parcial
C5: Cant. | D5: Part. % | E5: Cant. | F5: Part. % | G5: Cant. | H5: Part. % | I5: Cant. | J5: Part. % | K5: Cant. | L5: Part. % | M5: Cant. | N5: Part. % | O5: Cant. | P5: Part. %
A6: Total | C6: 2077069 | D6: 1 | E6: 108775 | F6: 1 | G6: 367675 | H6: 1 | I6: 7663 | J6: 1 | K6: 4576 | L6: 1 | M6: 44923 | N6: 1 | O6: 1543457 | P6: 1
A7: C.A.B.A. | C7: 257259 | D7: 0.12385674 | E7: 13224 | F7: 0.12157205 | G7: 41708 | H7: 0.11343714 | I7: 810 | J7: 0.10570273 | K7: 583 | L7: 0.12740385 | M7: 5388 | N7: 0.11993856 | O7: 195546 | P7: 0.12669352
A8: A.M.B.A. | C8: 914794 | D8: 0.44042543 | E8: 76627 | F8: 0.70445415 | G8: 191209 | H8: 0.52004896 | I8: 3031 | J8: 0.395537 | K8: 1914 | L8: 0.41826923 | M8: 19243 | N8: 0.42835519 | O8: 622770 | P8: 0.40349035
A9: Buenos Aires | C9: 963034 | D9: 0.46365046 | E9: 71861 | F9: 0.66063893 | G9: 191581 | H9: 0.52106072 | I9: 4318 | J9: 0.56348689 | K9: 2165 | L9: 0.47312063 | M9: 20561 | N9: 0.45769428 | O9: 672548 | P9: 0.43574133
B10: Gran La Plata | C10: 68406 | D10: 0.032933908 | E10: 3735 | F10: 0.034336934 | G10: 10949 | H10: 0.029779017 | I10: 345 | J10: 0.045021532 | K10: 110 | L10: 0.024038462 | M10: 1573 | N10: 0.035015471 | O10: 51694 | P10: 0.033492349
B11: Noreste | C11: 98702 | D11: 0.047519846 | E11: 3029 | F11: 0.027846472 | G11: 12124 | H11: 0.032974774 | I11: 252 | J11: 0.032885293 | K11: 184 | L11: 0.04020979 | M11: 2185 | N11: 0.048638782 | O11: 80928 | P11: 0.052432948
B12: Noroeste | C12: 67433 | D12: 0.03246546 | E12: 7144 | F12: 0.065676856 | G12: 12496 | H12: 0.033986537 | I12: 312 | J12: 0.040715125 | K12: 140 | L12: 0.030594406 | M12: 1332 | N12: 0.029650736 | O12: 46009 | P12: 0.029809058
B13: Norte Centro | C13: 85167 | D13: 0.041003452 | E13: 11171 | F13: 0.10269823 | G13: 21824 | H13: 0.059356769 | I13: 263 | J13: 0.034320762 | K13: 186 | L13: 0.040646853 | M13: 1808 | N13: 0.040246644 | O13: 49915 | P13: 0.032339741
B14: Oeste | C14: 47248 | D14: 0.022747439 | E14: 5256 | F14: 0.048319926 | G14: 12355 | H14: 0.033603046 | I14: 107 | J14: 0.0139632 | K14: 100 | L14: 0.021853147 | M14: 898 | N14: 0.01998976 | O14: 28532 | P14: 0.018485776
B15: Sur | C15: 34741 | D15: 0.016725973 | E15: 3091 | F15: 0.028416456 | G15: 7642 | H15: 0.02078466 | I15: 175 | J15: 0.022837009 | K15: 84 | L15: 0.018356643 | M15: 709 | N15: 0.015782561 | O15: 23040 | P15: 0.01492753
B16: Sureste | C16: 117348 | D16: 0.056496919 | E16: 10073 | F16: 0.092603999 | G16: 29943 | H16: 0.081438771 | I16: 383 | J16: 0.049980425 | K16: 252 | L16: 0.05506993 | M16: 2484 | N16: 0.055294615 | O16: 74213 | P16: 0.048082324
B17: Suroeste | C17: 138506 | D17: 0.066683389 | E17: 19904 | F17: 0.18298322 | G17: 42168 | H17: 0.11468824 | I17: 384 | J17: 0.050110923 | K17: 277 | L17: 0.060533217 | M17: 2867 | N17: 0.063820315 | O17: 72906 | P17: 0.047235524
B18: Bahía Blanca | C18: 21141 | D18: 0.010178285 | E18: 248 | F18: 0.0022799356 | G18: 965 | H18: 0.0026246005 | I18: 101 | J18: 0.013180217 | K18: 63 | L18: 0.013767483 | M18: 464 | N18: 0.010328785 | O18: 19300 | P18: 0.012504398
B19: Gral Pueyrredón | C19: 68512 | D19: 0.032984942 | E19: 3980 | F19: 0.03658929 | G19: 15780 | H19: 0.042918338 | I19: 204 | J19: 0.026621428 | K19: 117 | L19: 0.025568182 | M19: 1381 | N19: 0.030741491 | O19: 47050 | P19: 0.030483518
B20: Resto Bs As | C20: 215830 | D20: 0.10391085 | E20: 4230 | F20: 0.038887612 | G20: 25335 | H20: 0.068905963 | I20: 1792 | J20: 0.23385097 | K20: 652 | L20: 0.14248252 | M20: 4860 | N20: 0.10818512 | O20: 178961 | P20: 0.11594816
A21: Catamarca | C21: 4210 | D21: 0.0020268946 | E21: 49 | F21: 0.00045047116 | G21: 1230 | H21: 0.0033453458 | I21: 9 | J21: 0.0011744747 | K21: 2 | L21: 0.00043706294 | M21: 143 | N21: 0.0031832246 | O21: 2777 | P21: 0.0017992079
A22: Chaco | C22: 17261 | D22: 0.008310268 | E22: 416 | F22: 0.0038244082 | G22: 3274 | H22: 0.0089046033 | I22: 33 | J22: 0.0043064074 | K22: 24 | L22: 0.0052447552 | M22: 457 | N22: 0.010172963 | O22: 13057 | P22: 0.0084595813
A23: Chubut | C23: 40685 | D23: 0.019587698 | E23: 261 | F23: 0.0023994484 | G23: 6333 | H23: 0.017224451 | I23: 112 | J23: 0.014615686 | K23: 72 | L23: 0.015734266 | M23: 902 | N23: 0.020078802 | O23: 33005 | P23: 0.021383816
A24: Córdoba | C24: 185149 | D24: 0.089139552 | E24: 8123 | F24: 0.074677086 | G24: 34687 | H24: 0.09434147 | I24: 531 | J24: 0.06929401 | K24: 422 | L24: 0.09222028 | M24: 4179 | N24: 0.093025844 | O24: 137207 | P24: 0.088895901
B25: Córdoba capital | C25: 93030 | D25: 0.044789075 | E25: 5680 | F25: 0.052217881 | G25: 22057 | H25: 0.059990481 | I25: 187 | J25: 0.024402975 | K25: 145 | L25: 0.031687063 | M25: 1897 | N25: 0.042227812 | O25: 63064 | P25: 0.040858929
A26: Corrientes | C26: 14894 | D26: 0.0071706814 | E26: 134 | F26: 0.0012319007 | G26: 1922 | H26: 0.0052274427 | I26: 52 | J26: 0.0067858541 | K26: 27 | L26: 0.0059003497 | M26: 650 | N26: 0.014469203 | O26: 12109 | P26: 0.0078453757
A27: Entre Ríos | C27: 45917 | D27: 0.022106632 | E27: 325 | F27: 0.0029878189 | G27: 2189 | H27: 0.0059536275 | I27: 223 | J27: 0.029100874 | K27: 128 | L27: 0.027972028 | M27: 1052 | N27: 0.023417848 | O27: 42000 | P27: 0.027211642
A28: Formosa | C28: 4210 | D28: 0.0020268946 | E28: 46 | F28: 0.00042289129 | G28: 377 | H28: 0.0010253621 | I28: 26 | J28: 0.0033929271 | K28: 10 | L28: 0.0021853147 | M28: 156 | N28: 0.0034726087 | O28: 3595 | P28: 0.002329187
A29: Jujuy | C29: 7061 | D29: 0.0033995019 | E29: 44 | F29: 0.00040450471 | G29: 1744 | H29: 0.0047433195 | I29: 8 | J29: 0.0010439776 | K29: 11 | L29: 0.0024038462 | M29: 204 | N29: 0.0045411037 | O29: 5050 | P29: 0.0032718761
A30: La Pampa | C30: 18811 | D30: 0.0090565118 | E30: 80 | F30: 0.00073546311 | G30: 1086 | H30: 0.0029536955 | I30: 84 | J30: 0.010961764 | K30: 50 | L30: 0.010926573 | M30: 418 | N30: 0.0093048105 | O30: 17093 | P30: 0.011074491
A31: La Rioja | C31: 2378 | D31: 0.0011448825 | E31: 24 | F31: 0.00022063893 | G31: 404 | H31: 0.0010987965 | I31: 8 | J31: 0.0010439776 | K31: 6 | L31: 0.0013111888 | M31: 90 | N31: 0.0020034281 | O31: 1846 | P31: 0.0011960165
A32: Mendoza | C32: 91633 | D32: 0.044116493 | E32: 4766 | F32: 0.043815215 | G32: 21023 | H32: 0.057178214 | I32: 183 | J32: 0.023880987 | K32: 169 | L32: 0.036931818 | M32: 1999 | N32: 0.044498364 | O32: 63493 | P32: 0.041136877
B33: Gran Mendoza | C33: 56643 | D33: 0.02727064 | E33: 3605 | F33: 0.033141806 | G33: 14724 | H33: 0.040046236 | I33: 82 | J33: 0.01070077 | K33: 85 | L33: 0.018575175 | M33: 1134 | N33: 0.025243194 | O33: 37013 | P33: 0.023980584
A34: Misiones | C34: 13281 | D34: 0.0063941063 | E34: 174 | F34: 0.0015996323 | G34: 687 | H34: 0.001868498 | I34: 49 | J34: 0.0063943625 | K34: 25 | L34: 0.0054632867 | M34: 468 | N34: 0.010417826 | O34: 11878 | P34: 0.0076957116
A35: Neuquén | C35: 69713 | D35: 0.03356316 | E35: 1094 | F35: 0.010057458 | G35: 9506 | H35: 0.025854355 | I35: 133 | J35: 0.017356127 | K35: 107 | L35: 0.023382867 | M35: 1406 | N35: 0.031297999 | O35: 57467 | P35: 0.037232654
A36: Río Negro | C36: 29189 | D36: 0.014052976 | E36: 412 | F36: 0.003787635 | G36: 3139 | H36: 0.0085374312 | I36: 84 | J36: 0.010961764 | K36: 51 | L36: 0.011145105 | M36: 568 | N36: 0.012643857 | O36: 24935 | P36: 0.016155293
A37: Salta | C37: 6131 | D37: 0.0029517556 | E37: 69 | F37: 0.00063433693 | G37: 1019 | H37: 0.0027714694 | I37: 10 | J37: 0.0013049719 | K37: 11 | L37: 0.0024038462 | M37: 213 | N37: 0.0047414465 | O37: 4809 | P37: 0.0031157331
A38: San Juan | C38: 14647 | D38: 0.0070517638 | E38: 96 | F38: 0.00088255573 | G38: 2203 | H38: 0.0059917046 | I38: 13 | J38: 0.0016964635 | K38: 53 | L38: 0.011582168 | M38: 303 | N38: 0.0067448746 | O38: 11979 | P38: 0.0077611492
A39: San Luis | C39: 13354 | D39: 0.006429252 | E39: 141 | F39: 0.0012962537 | G39: 1986 | H39: 0.0054015095 | I39: 51 | J39: 0.0066553569 | K39: 43 | L39: 0.0093968531 | M39: 337 | N39: 0.0075017252 | O39: 10796 | P39: 0.0069946879
A40: Santa Cruz | C40: 14647 | D40: 0.0070517638 | E40: 96 | F40: 0.00088255573 | G40: 2203 | H40: 0.0059917046 | I40: 13 | J40: 0.0016964635 | K40: 53 | L40: 0.011582168 | M40: 303 | N40: 0.0067448746 | O40: 11979 | P40: 0.0077611492
A41: Santa Fe | C41: 203082 | D41: 0.097773353 | E41: 6705 | F41: 0.061641002 | G41: 26918 | H41: 0.073211396 | I41: 767 | J41: 0.10009135 | K41: 451 | L41: 0.098557692 | M41: 3459 | N41: 0.07699842 | O41: 164782 | P41: 0.10676164
...

Sheet Cuadro 10
A1: AUTOMOTORES - Coberturas de Casco | R1: INDICE
A2: Cuadro 10: Frecuencia Siniestral de Casco por Hecho Generador. Principales Zonas. Año 2024. Comparación con año 2023
A4: Jurisdicción | C4: Total | E4: Robo Total | G4: Robo Parcial | I4: Incendio Total | K4: Incendio Parcial | M4: Daño Total | O4: Daño Parcial
C5: Frec. Sin. | D5: Var. (en p.p.)* | E5: Frec. Sin. | F5: Var. (en p.p.)* | G5: Frec. Sin. | H5: Var. (en p.p.)* | I5: Frec. Sin. | J5: Var. (en p.p.)* | K5: Frec. Sin. | L5: Var. (en p.p.)* | M5: Frec. Sin. | N5: Var. (en p.p.)* | O5: Frec. Sin. | P5: Var. (en p.p.)*
A6: Total | C6: 0.21554179 | D6: -0.53 | E6: 0.011287809 | F6: 0.09 | G6: 0.052046992 | H6: -0.43 | I6: 0.00079520552 | J6: 0.02 | K6: 0.00047486108 | L6: 0 | M6: 0.0046617536 | N6: 0.02 | O6: 0.55353547 | P6: -2.08
A7: C.A.B.A. | C7: 0.24796783 | D7: -0.5 | E7: 0.012746402 | F7: 0.05 | G7: 0.04782699 | H7: -0.57 | I7: 0.00078074602 | J7: 0.02 | K7: 0.00056194436 | L7: 0.01 | M7: 0.0051934068 | N7: 0.04 | O7: 0.48096312 | P7: -4.01
A8: A.M.B.A. | C8: 0.24014399 | D8: 0.64 | E8: 0.020115473 | F8: 0.23 | G8: 0.063663955 | H8: -0.33 | I8: 0.00079567252 | J8: 0.02 | K8: 0.00050244711 | L8: 0 | M8: 0.0050515098 | N8: 0.06 | O8: 0.49766726 | P8: -0.44
A9: Buenos Aires | C9: 0.22570477 | D9: 0.34 | E9: 0.01684195 | F9: 0.21 | G9: 0.059940361 | H9: -0.12 | I9: 0.0010120029 | J9: 0.03 | K9: 0.00050740766 | L9: 0 | M9: 0.0048188494 | N9: 0.04 | O9: 0.51929325 | P9: 0.2
B10: Gran La Plata | C10: 0.23968576 | D10: 1.41 | E10: 0.013086956 | F10: 0.2 | G10: 0.04828188 | H10: 0.54 | I10: 0.0012088353 | J10: 0.04 | K10: 0.00038542574 | L10: 0 | M10: 0.0055115882 | N10: 0.09 | O10: 0.42869209 | P10: 4.55
B11: Noreste | C11: 0.20158045 | D11: -0.5 | E11: 0.0061861682 | F11: -0.03 | G11: 0.030146912 | H11: -0.3 | I11: 0.00051466305 | J11: 0.01 | K11: 0.00037578572 | L11: 0 | M11: 0.0044624554 | N11: 0.02 | O11: 0.45833625 | P11: -5.84
B12: Noroeste | C12: 0.22222768 | D12: 0.7 | E12: 0.023543288 | F12: 0.46 | G12: 0.056003836 | H12: -0.39 | I12: 0.0010282063 | J12: 0.04 | K12: 0.00046137463 | L12: -0.02 | M12: 0.0043896501 | N12: 0.02 | O12: 0.56567744 | P12: -0.9
B13: Norte Centro | C13: 0.2247011 | D13: 0.89 | E13: 0.029473106 | F13: 0.34 | G13: 0.076000949 | H13: -0.04 | I13: 0.00069388835 | J13: 0.02 | K13: 0.00049073473 | L13: 0 | M13: 0.0047701526 | N13: 0.05 | O13: 0.48282491 | P13: -1.35
B14: Oeste | C14: 0.24955562 | D14: 1.63 | E14: 0.027761267 | F14: 0.55 | G14: 0.085260764 | H14: 0.1 | I14: 0.00056515517 | J14: 0.01 | K14: 0.0005281824 | L14: 0 | M14: 0.004743078 | N14: 0.07 | O14: 0.47985566 | P14: 1.72
B15: Sur | C15: 0.23438456 | D15: 2.38 | E15: 0.020853824 | F15: 0.21 | G15: 0.068329767 | H15: -0.48 | I15: 0.0011806597 | J15: 0.03 | K15: 0.00056671666 | L15: 0.01 | M15: 0.0047833584 | N15: 0.05 | O15: 0.58708376 | P15: 6.18
B16: Sureste | C16: 0.2556471 | D16: 1.82 | E16: 0.021944416 | F16: 0.3 | G16: 0.08822666 | H16: -0.33 | I16: 0.00083438014 | J16: 0.02 | K16: 0.00054899163 | L16: 0 | M16: 0.005411489 | N16: 0.1 | O16: 0.59274243 | P16: 7.06
B17: Suroeste | C17: 0.26748485 | D17: 1.29 | E17: 0.038438901 | F17: 0.62 | G17: 0.10648568 | H17: 0.02 | I17: 0.00074158651 | J17: 0.02 | K17: 0.00053494652 | L17: 0 | M17: 0.005536793 | N17: 0.11 | O17: 0.52439237 | P17: 1.5
B18: Bahía Blanca | C18: 0.18503085 | D18: -1.58 | E18: 0.0021705525 | F18: 0.03 | G18: 0.01170005 | H18: -0.13 | I18: 0.00088397501 | J18: 0.02 | K18: 0.00055139035 | L18: 0.01 | M18: 0.0040610337 | N18: -0.06 | O18: 0.588709 | P18: -1.64
B19: Gral Pueyrredón | C19: 0.33825275 | D19: -1.82 | E19: 0.019649783 | F19: 0.6 | G19: 0.092879016 | H19: -0.29 | I19: 0.0010071748 | J19: 0.02 | K19: 0.00057764438 | L19: -0.01 | M19: 0.0068181786 | N19: 0.07 | O19: 0.60361184 | P19: -6.11
B20: Resto Bs As | C20: 0.1832024 | D20: -0.66 | E20: 0.0035905396 | F20: 0.02 | G20: 0.031182838 | H20: 0.1 | I20: 0.0015210986 | J20: 0.05 | K20: 0.00055343542 | L20: 0 | M20: 0.0041253008 | N20: -0.03 | O20: 0.52700042 | P20: -0.93
B21: Córdoba capital | C21: 0.29435832 | D21: -4.78 | E21: 0.017972216 | F21: 0.1 | G21: 0.092881173 | H21: -3.34 | I21: 0.00059169091 | J21: 0.01 | K21: 0.00045879776 | L21: 0 | M21: 0.0060023404 | N21: 0 | O21: 0.80252688 | P21: -6.63
... B23: Rosario | C23: 0.34262872 | D23: 0.82 | E23: 0.015166906 | F23: -0.12 | G23: 0.098605918 | H23: -1.39 | I23: 0.00080370928 | J23: 0 | K23: 0.00076228097 | L23: 0.02 | M23: 0.0041138315 | N23: 0.02 | O23: 0.77099053 | P23: 8.94
A24: Resto del País | C24: 0.17405155 | D24: -4.44 | E24: 0.0029967581 | F24: -0.14 | G24: 0.033224686 | H24: -1.69 | I24: 0.00057847923 | J24: 0.01 | K24: 0.00038658796 | L24: -0.01 | M24: 0.0041382867 | N24: -0.08 | O24: 0.58337903 | P24: -14.37
A26: * puntos porcentuales
A28: Zona Gran La Plata, integrada por los partidos de Berisso, Ensenada y La Plata.
A29: Zona Sur, integrada por los partidos de Esteban Echeverría, Ezeiza, Presidente Perón y San Vicente.
A30: Zona Sureste, integrada por los partidos de Almirante Brown, Avellaneda, Berazategui, Florencio Varela y Quilmes.
A31: Zona Suroeste, integrada por los partidos de La Matanza, Lanús y Lomas de Zamora.
A32: Zona Noreste, integrada por los partidos de Escobar, San Fernando, San Isidro, Tigre y Vicente López.
A33: Zona Noroeste, integrada por los partidos de General Rodríguez, Merlo, Moreno y Pilar.
A34: Zona Norte Centro, integrada por los partidos de General San Martín, José C. Paz, Malvinas Argentinas, San Miguel y Tres de Febrero
A35: Zona Oeste, integrada por los partidos de Hurlingham, Ituzaingó, Morón.

Sheet Cuadro 11
A1: AUTOMOTORES - Coberturas de Casco | P1: INDICE
A2: Cuadro 11: Siniestros de Robo Total por Tipo de Vehículo. Por año
A4: Tipo de Vehículo | B4: Año | L4: Part. 2024 | M4: Var. | N4: Var.
M5: (24 / 23) | N5: (24 / 15)
B6: 2015 | C6: 2016 | D6: 2017 | E6: 2018 | F6: 2019 | G6: 2020 | H6: 2021 | I6: 2022 | J6: 2023 | K6: 2024 | L6: % | M6: % | N6: %
A7: Total | B7: 66872 | C7: 69988 | D7: 68320 | E7: 68736 | F7: 74237 | G7: 54257 | H7: 65867 | I7: 83572 | J7: 104051 | K7: 108775 | L7: 1 | M7: 0.045400813 | N7: 0.62661503
A8: Autos | B8: 45014 | C8: 44221 | D8: 42975 | E8: 39654 | F8: 41403 | G8: 29065 | H8: 37604 | I8: 42981 | J8: 51906 | K8: 57018 | L8: 0.52418295 | M8: 0.098485724 | N8: 0.26667259
A9: Camionetas | B9: 2506 | C9: 2532 | D9: 2421 | E9: 2309 | F9: 2593 | G9: 1913 | H9: 2393 | I9: 2636 | J9: 3040 | K9: 3343 | L9: 0.030733165 | M9: 0.099671053 | N9: 0.3339984
A10: Camiones | B10: 941 | C10: 865 | D10: 725 | E10: 543 | F10: 577 | G10: 645 | H10: 660 | I10: 536 | J10: 551 | K10: 508 | L10: 0.0046701908 | M10: -0.078039927 | N10: -0.46014878
A11: Taxis | B11: 233 | C11: 251 | D11: 246 | E11: 266 | F11: 296 | G11: 220 | H11: 246 | I11: 164 | J11: 166 | K11: 217 | L11: 0.0019949437 | M11: 0.30722892 | N11: -0.068669528
A12: Remises | B12: 708 | C12: 748 | D12: 802 | E12: 720 | F12: 699 | G12: 407 | H12: 497 | I12: 378 | J12: 365 | K12: 334 | L12: 0.0030705585 | M12: -0.084931507 | N12: -0.52824859
A13: Motos | B13: 17120 | C13: 21029 | D13: 20858 | E13: 24961 | F13: 28378 | G13: 21800 | H13: 24277 | I13: 36678 | J13: 47829 | K13: 47168 | L13: 0.43362905 | M13: -0.013820067 | N13: 1.7551402
A14: Máquinas Rurales | B14: 272 | C14: 253 | D14: 197 | E14: 187 | F14: 192 | G14: 157 | H14: 132 | I14: 122 | J14: 124 | K14: 117 | L14: 0.0010756148 | M14: -0.056451613 | N14: -0.56985294
A15: M1+M2+M3 | B15: 78 | C15: 89 | D15: 96 | E15: 96 | F15: 99 | G15: 50 | H15: 58 | I15: 77 | J15: 70 | K15: 70 | L15: 0.00064353022 | M15: 0 | N15: -0.1025641
A17: Autos | B17: Autómoviles, camionetas rurales, breaks, jeeps hasta 4 cilindros, pick up A.
A18: Camionetas | B18: Jeeps más de 4 cilindros, pick up B, casas rodantes con propulsión propia.
A19: Camiones | B19: Camiones, semitracción.
A20: Máquinas Rurales | B20: Tractores, máquinas rurales, acoplados para trabajos rurales, acoplados, furgones, semirremolques, casas rodantes sin propulsión propia, trailer, bantam.
A21: M1+M2+M3 | B21: M1: vehículo para transporte de pasajeros, que no contenga más de 8 asientos además del asiento del conductor y que cargado no exceda de un peso máximo de 3500 Kg.
B22: M2: vehículo para transporte de pasajeros con más de 8 asientos excluyendo el asiento del conductor, y que no exceda el peso máximo de 5000 Kg.
B23: M3: vehículo para transporte de pasajeros con más de 8 asientos excluyendo el asiento del conductor, y que tenga un peso mayor a los 5000 Kg.

Sheet Cuadro 12
A1: AUTOMOTORES - Coberturas de Casco | P1: INDICE
A2: Cuadro 12: Vehículos Expuestos a Riesgo con cobertura de Robo Total por Tipo de Vehículo. Por año
A4: Tipo de Vehículo | B4: Año | L4: Part. 2024 | M4: Var. | N4: Var.
M5: (24 / 23) | N5: (24 / 15)
B6: 2015 | C6: 2016 | D6: 2017 | E6: 2018 | F6: 2019 | G6: 2020 | H6: 2021 | I6: 2022 | J6: 2023 | K6: 2024 | L6: % | M6: % | N6: %
A7: Total | B7: 7580419.7 | C7: 7851196.5 | D7: 8335592.4 | E7: 9076953.8 | F7: 9282478.3 | G7: 9203307.4 | H7: 9583139 | I7: 9738817.2 | J7: 10044846 | K7: 9636506.3 | L7: 1 | M7: -0.04065164 | N7: 0.27123651
A8: Autos | B8: 6313946.5 | C8: 6462828.3 | D8: 6810633.7 | E8: 7350312.1 | F8: 7511947.2 | G8: 7417409.8 | H8: 7639717.4 | I8: 7619569.1 | J8: 7770306.9 | K8: 7397924.5 | L8: 0.76769778 | M8: -0.047923766 | N8: 0.17167995
A9: Camionetas | B9: 519040.42 | C9: 556239.51 | D9: 600282.54 | E9: 671159.61 | F9: 704803.38 | G9: 693850.01 | H9: 737858.18 | I9: 766580.76 | J9: 783609.34 | K9: 799623.16 | L9: 0.082978533 | M9: 0.020435975 | N9: 0.54057976
A10: Camiones | B10: 188063.12 | C10: 188362.52 | D10: 198079.33 | E10: 203522.27 | F10: 204168.91 | G10: 198650.65 | H10: 197710.79 | I10: 206643.33 | J10: 218177.69 | K10: 210163.64 | L10: 0.021809111 | M10: -0.036731751 | N10: 0.11751647
A11: Taxis | B11: 52630.753 | C11: 53740.008 | D11: 51706.329 | E11: 60996.305 | F11: 58560.629 | G11: 49255.462 | H11: 43487.978 | I11: 34388.618 | J11: 25725.131 | K11: 23514.392 | L11: 0.0024401366 | M11: -0.085936956 | N11: -0.55321954
A12: Remises | B12: 46558.62 | C12: 49904.961 | D12: 48294.54 | E12: 43003.33 | F12: 39089.641 | G12: 34160.218 | H12: 35999.085 | I12: 25244.024 | J12: 35914.231 | K12: 17582.704 | L12: 0.0018245933 | M12: -0.51042514 | N12: -0.6223534
A13: Motos | B13: 316425.44 | C13: 398847.42 | D13: 481121.33 | E13: 601411 | F13: 617721.14 | G13: 659971.58 | H13: 776682.56 | I13: 925957.03 | J13: 1014662 | K13: 986112.47 | L13: 0.10233091 | M13: -0.028136991 | N13: 2.1164133
A14: Máquinas Rurales | B14: 113766.52 | C14: 111263.77 | D14: 115452.5 | E14: 115468.19 | F14: 114277.01 | G14: 114198.05 | H14: 121436.92 | I14: 128662.33 | J14: 150572.63 | K14: 155081.06 | L14: 0.016093079 | M14: 0.029941839 | N14: 0.36315192
A15: M1+M2+M3 | B15: 29988.329 | C15: 30010.021 | D15: 30022.141 | E15: 31081.051 | F15: 31910.397 | G15: 35811.681 | H15: 30246.171 | I15: 31772.018 | J15: 45877.882 | K15: 46504.41 | L15: 0.0048258579 | M15: 0.01365644 | N15: 0.5507503
A17: Autos | B17: Autómoviles, camionetas rurales, breaks, jeeps hasta 4 cilindros, pick up A.
A18: Camionetas | B18: Jeeps más de 4 cilindros, pick up B, casas rodantes con propulsión propia.
A19: Camiones | B19: Camiones, semitracción.
A20: Máquinas Rurales | B20: Tractores, máquinas rurales, acoplados para trabajos rurales, acoplados, furgones, semirremolques, casas rodantes sin propulsión propia, trailer, bantam.
A21: M1+M2+M3 | B21: M1: vehículo para transporte de pasajeros, que no contenga más de 8 asientos además del asiento del conductor y que cargado no exceda de un peso máximo de 3500 Kg.
B22: M2: vehículo para transporte de pasajeros con más de 8 asientos excluyendo el asiento del conductor, y que no exceda el peso máximo de 5000 Kg.
B23: M3: vehículo para transporte de pasajeros con más de 8 asientos excluyendo el asiento del conductor, y que tenga un peso mayor a los 5000 Kg.

Sheet Cuadro 13
A1: AUTOMOTORES - Coberturas de Casco | N1: INDICE
A2: Cuadro 13: Frecuencia Siniestral de Robo Total por Tipo de Vehículo. Por año
A4: Tipo de Vehículo | B4: Año | L4: Var. (en p.p.)*
B5: 2015 | C5: 2016 | D5: 2017 | E5: 2018 | F5: 2019 | G5: 2020 | H5: 2021 | I5: 2022 | J5: 2023 | K5: 2024
A6: Total | B6: 0.0088216751 | C6: 0.0089143101 | D6: 0.0081961781 | E6: 0.0075725845 | F6: 0.0079975409 | G6: 0.0058953806 | H6: 0.0068732176 | I6: 0.0085813296 | J6: 0.010358646 | K6: 0.011287805 | L6: 0.09
A7: Autos | B7: 0.007129297 | C7: 0.0068423603 | D7: 0.0063099855 | E7: 0.005394873 | F7: 0.0055116202 | G7: 0.0039184838 | H7: 0.0049221716 | I7: 0.0056408702 | J7: 0.0066800451 | K7: 0.0077072968 | L7: 0.1
A8: Camionetas | B8: 0.0048281404 | C8: 0.0045519959 | D8: 0.0040331008 | E8: 0.0034403143 | F8: 0.0036790403 | G8: 0.00275708 | H8: 0.0032431706 | I8: 0.0034386462 | J8: 0.0038794841 | K8: 0.0041807193 | L8: 0.03
A9: Camiones | B9: 0.0050036391 | C9: 0.0045922086 | D9: 0.0036601496 | E9: 0.0026680127 | F9: 0.0028260915 | G9: 0.0032469061 | H9: 0.0033382093 | I9: 0.0025938413 | J9: 0.0025254645 | K9: 0.0024171641 | L9: -0.01
A10: Taxis | B10: 0.0044270695 | C10: 0.0046706357 | D10: 0.0047576381 | E10: 0.0043609199 | F10: 0.0050545905 | G10: 0.0044665097 | H10: 0.0056567357 | I10: 0.0047690197 | J10: 0.0064528339 | K10: 0.0092283909 | L10: 0.27
A11: Remises | B11: 0.015206636 | C11: 0.01498849 | D11: 0.016606432 | E11: 0.016742889 | F11: 0.017881976 | G11: 0.011914444 | H11: 0.013805906 | I11: 0.014973841 | J11: 0.010163102 | K11: 0.01899594 | L11: 0.88
A12: Motos | B12: 0.054104372 | C12: 0.052724423 | D12: 0.043352889 | E12: 0.041504063 | F12: 0.045939823 | G12: 0.033031725 | H12: 0.0312573 | I12: 0.039610909 | J12: 0.047137864 | K12: 0.047832272 | L12: 0.07
A13: Máquinas Rurales | B13: 0.0023908615 | C13: 0.0022738758 | D13: 0.0017063294 | E13: 0.0016194937 | F13: 0.001680128 | G13: 0.0013748045 | H13: 0.0010869841 | I13: 0.00094821852 | J13: 0.00082352282 | K13: 0.00075444418 | L13: 0
A14: M1+M2+M3 | B14: 0.0026010119 | C14: 0.002965676 | D14: 0.00319764 | E14: 0.0030886987 | F14: 0.0031024371 | G14: 0.0013961925 | H14: 0.0019175981 | I14: 0.0024235162 | J14: 0.0015257897 | K14: 0.0015052336 | L14: 0
A16: * puntos porcentuales
A18: Autos | B18: Autómoviles, camionetas rurales, breaks, jeeps hasta 4 cilindros, pick up A.
A19: Camionetas | B19: Jeeps más de 4 cilindros, pick up B, casas rodantes con propulsión propia.
A20: Camiones | B20: Camiones, semitracción.
A21: Máquinas Rurales | B21: Tractores, máquinas rurales, acoplados para trabajos rurales, acoplados, furgones, semirremolques, casas rodantes sin propulsión propia, trailer, bantam.
A22: M1+M2+M3 | B22: M1: vehículo para transporte de pasajeros, que no contenga más de 8 asientos además del asiento del conductor y que cargado no exceda de un peso máximo de 3500 Kg.
B23: M2: vehículo para transporte de pasajeros con más de 8 asientos excluyendo el asiento del conductor, y que no exceda el peso máximo de 5000 Kg.
B24: M3: vehículo para transporte de pasajeros con más de 8 asientos excluyendo el asiento del conductor, y que tenga un peso mayor a los 5000 Kg.

Sheet Cuadro 14
A1: AUTOMOTORES - Coberturas de Casco | J1: INDICE
A2: Cuadro 14: Siniestros de Robo Total por Mes de ocurrencia
A4: Mes | B4: 2024 | C4: prom. Diario | D4: Part. % | E4: 2023 | F4: prom. Diario | G4: Part. % | H4: Var.
H5: (24 / 23)
H6: %
A7: Total | B7: 108775 | C7: 298.0137 | D7: 1 | E7: 104051 | F7: 285.07123 | G7: 1 | H7: 0.045400813
A8: Enero | B8: 9981 | C8: 321.96774 | D8: 0.091758217 | E8: 8584 | F8: 276.90323 | G8: 0.082498006 | H8: 0.16274464
A9: Febrero | B9: 10108 | C9: 361 | D9: 0.092925764 | E9: 8279 | F9: 295.67857 | G9: 0.079566751 | H9: 0.2209204
A10: Marzo | B10: 10313 | C10: 332.67742 | D10: 0.094810388 | E10: 10138 | F10: 327.03226 | G10: 0.09743299 | H10: 0.017261787
A11: Abril | B11: 9738 | C11: 324.6 | D11: 0.089524247 | E11: 8903 | F11: 296.76667 | G11: 0.08556381 | H11: 0.093788611
A12: Mayo | B12: 9933 | C12: 320.41935 | D12: 0.091316939 | E12: 8419 | F12: 271.58065 | G12: 0.080912245 | H12: 0.17983133
A13: Junio | B13: 8622 | C13: 287.4 | D13: 0.079264537 | E13: 8232 | F13: 274.4 | G13: 0.079115049 | H13: 0.047376093
A14: Julio | B14: 8864 | C14: 285.93548 | D14: 0.081489313 | E14: 8538 | F14: 275.41935 | G14: 0.082055915 | H14: 0.038182244
A15: Agosto | B15: 8423 | C15: 271.70968 | D15: 0.077435072 | E15: 8605 | F15: 277.58065 | G15: 0.08269983 | H15: -0.021150494
A16: Septiembre | B16: 8274 | C16: 275.8 | D16: 0.076065272 | E16: 8097 | F16: 269.9 | G16: 0.077817609 | H16: 0.021859948
A17: Octubre | B17: 8362 | C17: 269.74194 | D17: 0.076874282 | E17: 8195 | F17: 264.35484 | G17: 0.078759454 | H17: 0.020378279
A18: Noviembre | B18: 8232 | C18: 274.4 | D18: 0.075679154 | E18: 8486 | F18: 282.86667 | G18: 0.08155616 | H18: -0.029931652
A19: Diciembre | B19: 7925 | C19: 255.64516 | D19: 0.072856815 | E19: 9575 | F19: 308.87097 | G19: 0.092022181 | H19: -0.17232376

Sheet Cuadro 15
A1: AUTOMOTORES - Coberturas de Casco | L1: INDICE
A2: Cuadro 15: Siniestros de Robo Total por Tipo de Vehículo y Mes de ocurrencia. Año 2024
B4: Total | C4: Autos | D4: Camionetas | E4: Camiones | F4: Taxis | G4: Remises | H4: Motos | I4: Máq Rurales | J4: M1+M2+M3
A5: Mes | B5: 108775 | C5: 57018 | D5: 3343 | E5: 508 | F5: 217 | G5: 334 | H5: 47168 | I5: 117 | J5: 70
A6: Enero | B6: 9981 | C6: 4897 | D6: 272 | E6: 35 | F6: 13 | G6: 38 | H6: 4717 | I6: 3 | J6: 6
A7: Febrero | B7: 10108 | C7: 5144 | D7: 258 | E7: 34 | F7: 18 | G7: 24 | H7: 4615 | I7: 10 | J7: 5
A8: Marzo | B8: 10313 | C8: 5570 | D8: 332 | E8: 41 | F8: 15 | G8: 29 | H8: 4304 | I8: 14 | J8: 8
A9: Abril | B9: 9738 | C9: 5512 | D9: 291 | E9: 39 | F9: 21 | G9: 38 | H9: 3829 | I9: 5 | J9: 3
A10: Mayo | B10: 9933 | C10: 5355 | D10: 304 | E10: 43 | F10: 20 | G10: 36 | H10: 4154 | I10: 15 | J10: 6
A11: Junio | B11: 8622 | C11: 4543 | D11: 287 | E11: 37 | F11: 33 | G11: 36 | H11: 3677 | I11: 8 | J11: 1
A12: Julio | B12: 8864 | C12: 4593 | D12: 266 | E12: 41 | F12: 20 | G12: 31 | H12: 3896 | I12: 8 | J12: 9
A13: Agosto | B13: 8423 | C13: 4522 | D13: 284 | E13: 49 | F13: 23 | G13: 24 | H13: 3498 | I13: 14 | J13: 9
A14: Septiembre | B14: 8274 | C14: 4258 | D14: 276 | E14: 53 | F14: 14 | G14: 20 | H14: 3639 | I14: 6 | J14: 8
A15: Octubre | B15: 8362 | C15: 4271 | D15: 256 | E15: 59 | F15: 18 | G15: 24 | H15: 3714 | I15: 15 | J15: 5
A16: Noviembre | B16: 8232 | C16: 4287 | D16: 260 | E16: 46 | F16: 8 | G16: 17 | H16: 3597 | I16: 15 | J16: 2
A17: Diciembre | B17: 7925 | C17: 4066 | D17: 257 | E17: 31 | F17: 14 | G17: 17 | H17: 3528 | I17: 4 | J17: 8
A19: Autos | B19: Autómoviles, camionetas rurales, breaks, jeeps hasta 4 cilindros, pick up A.
A20: Camionetas | B20: Jeeps más de 4 cilindros, pick up B, casas rodantes con propulsión propia.
A21: Camiones | B21: Camiones, semitracción.
A22: Máquinas Rurales | B22: Tractores, máquinas rurales, acoplados para trabajos rurales, acoplados, furgones, semirremolques, casas rodantes sin propulsión propia, trailer, bantam.
A23: M1+M2+M3 | B23: M1: vehículo para transporte de pasajeros, que no contenga más de 8 asientos además del asiento del conductor y que cargado no exceda de un peso máximo de 3500 Kg.
B24: M2: vehículo para transporte de pasajeros con más de 8 asientos excluyendo el asiento del conductor, y que no exceda el peso máximo de 5000 Kg.
B25: M3: vehículo para transporte de pasajeros con más de 8 asientos excluyendo el asiento del conductor, y que tenga un peso mayor a los 5000 Kg.

Sheet Cuadro 16
A1: AUTOMOTORES - Coberturas de Casco | H1: INDICE
A2: Cuadro 16: Siniestros de Robo Total por Jurisdicción. Año 2024
A4: Jurisdicción | C4: Cantidad de Siniestros de Robo Total | D4: Part. % | E4: Frecuencia Siniestral | F4: Var. (en p.p.)*
A5: Total | C5: 108775 | D5: 1 | E5: 0.011287809 | F5: 0.09
A6: C.A.B.A. | C6: 13224 | D6: 0.12157205 | E6: 0.012746402 | F6: 0.05
A7: A.M.B.A. | C7: 76627 | D7: 0.70445415 | E7: 0.020115473 | F7: 0.17
A8: Buenos Aires | C8: 71861 | D8: 0.66063893 | E8: 0.01684195 | F8: 0.21
B9: Gran La Plata | C9: 3735 | D9: 0.034336934 | E9: 0.013086956 | F9: 0.03
B10: Noreste | C10: 3029 | D10: 0.027846472 | E10: 0.0061861682 | F10: -0.05
B11: Noroeste | C11: 7144 | D11: 0.065676856 | E11: 0.023543288 | F11: 0.4
B12: Norte Centro | C12: 11171 | D12: 0.10269823 | E12: 0.029473106 | F12: 0.25
B13: Oeste | C13: 5256 | D13: 0.048319926 | E13: 0.027761267 | F13: 0.41
B14: Sur | C14: 3091 | D14: 0.028416456 | E14: 0.020853824 | F14: 0.16
B15: Sureste | C15: 10073 | D15: 0.092603999 | E15: 0.021944416 | F15: 0.19
B16: Suroeste | C16: 19904 | D16: 0.18298322 | E16: 0.038438901 | F16: 0.53
B17: Bahía Blanca | C17: 248 | D17: 0.0022799356 | E17: 0.0021705525 | F17: 0.02
B18: Gral Pueyrredón | C18: 3980 | D18: 0.03658929 | E18: 0.019649783 | F18: 0.68
B19: Resto Bs As | C19: 4230 | D19: 0.038887612 | E19: 0.0035905396 | F19: -0.01
A20: Catamarca | C20: 49 | D20: 0.00045047116 | E20: 0.0012038702 | F20: 0.02
A21: Chaco | C21: 416 | D21: 0.0038244082 | E21: 0.0034991982 | F21: -0.02
A22: Chubut | C22: 261 | D22: 0.0023994484 | E22: 0.0017189395 | F22: -0.06
A23: Córdoba | C23: 8123 | D23: 0.074677086 | E23: 0.0085142424 | F23: 0.07
B24: Córdoba capital | C24: 5680 | D24: 0.052217881 | E24: 0.017972216 | F24: 0.08
A25: Corrientes | C25: 134 | D25: 0.0012319007 | E25: 0.0013011557 | F25: 0.02
A26: Entre Ríos | C26: 325 | D26: 0.0029878189 | E26: 0.0012137884 | F26: 0
A27: Formosa | C27: 46 | D27: 0.00042289129 | E27: 0.0011623853 | F27: 0.02
